<?xml version="1.0" encoding="utf-8" ?>
<!-- =================================================================================== -->
<!-- |    This document was autogenerated by xacro from /home/jove/catkin_ws/src/hharm_description/urdf/hharm.xacro | -->
<!-- |    EDITING THIS FILE BY HAND IS NOT RECOMMENDED                                 | -->
<!-- =================================================================================== -->
<robot name="hharm" xmlns:xacro="http://ros.org/wiki/xacro">
    <!-- Defining the colors used in this robot -->
    <material name="Black">
        <color rgba="0 0 0 1" />
    </material>
    <material name="White">
        <color rgba="1 1 1 1" />
    </material>
    <material name="Blue">
        <color rgba="0 0 1 1" />
    </material>
    <material name="Red">
        <color rgba="1 0 0 1" />
    </material>
    <!-- bottom_joint -->
    <joint name="bottom_joint" type="fixed">
        <origin rpy="0 0 0" xyz="0 0 0" />
        <parent link="base_link" />
        <child link="bottom_link" />
    </joint>
    <link name="bottom_link">
        <visual>
            <origin rpy="0 0 0" xyz=" 0 0 -0.02" />
            <geometry>
                <box size="1 1 0.02" />
            </geometry>
            <material name="Brown" />
        </visual>
        <collision>
            <origin rpy="0 0 0" xyz=" 0 0 -0.02" />
            <geometry>
                <box size="1 1 0.02" />
            </geometry>
        </collision>
        
<inertial>
            <mass value="500" />
            <inertia ixx="1.0" ixy="0.0" ixz="0.0" iyy="0.5" iyz="0.0" izz="1.0" />
        </inertial>

    </link>
    <!--  BASE LINK  -->
    <link name="base_link">
        <visual>
            <origin rpy="0 0 0" xyz="0 0 0" />
            <geometry>
                <box size="0.1 0.1 0.04" />
            </geometry>
            <material name="White" />
        </visual>
        <collision>
            <origin rpy="0 0 0" xyz="0 0 0" />
            <geometry>
                <box size="0.1 0.1 0.04" />
            </geometry>
        </collision>
        
<inertial>
            <mass value="1" />
            <inertia ixx="1.0" ixy="0.0" ixz="0.0" iyy="0.5" iyz="0.0" izz="1.0" />
        </inertial>

    </link>
    <joint name="joint1" type="revolute">
        <parent link="base_link" />
        <child link="link1" />
        <origin rpy="0 1.570795 0" xyz="0 0 0.02" />
        <axis xyz="-1 0 0" />
        <limit effort="300" lower="-2.96" upper="2.96" velocity="1" />
        <dynamics damping="50" friction="1" />
    </joint>
    <!-- LINK1 -->
    <link name="link1">
        <visual>
            <origin rpy="0 1.570795 0" xyz="-0.05 0 0" />
            <geometry>
                <cylinder length="0.1" radius="0.03" />
            </geometry>
            <material name="Blue" />
        </visual>
        <collision>
            <origin rpy="0 1.570795 0" xyz="-0.05 0 0" />
            <geometry>
                <cylinder length="0.1" radius="0.03" />
            </geometry>
        </collision>
        
<inertial>
            <mass value="1" />
            <inertia ixx="1.0" ixy="0.0" ixz="0.0" iyy="0.5" iyz="0.0" izz="1.0" />
        </inertial>

    </link>
    <joint name="joint2" type="revolute">
        <parent link="link1" />
        <child link="link2" />
        <origin rpy="-1.570795 0 1.570795" xyz="-0.1 0 0.0" />
        <axis xyz="1 0 0" />
        <limit effort="300" lower="-2.35" upper="2.35" velocity="1" />
        <dynamics damping="50" friction="1" />
    </joint>
    <!-- LINK2 -->
    <link name="link2">
        <visual>
            <origin rpy="0 0 0" xyz="0 0 0.07" />
            <geometry>
                <cylinder length="0.14" radius="0.03" />
            </geometry>
            <material name="White" />
        </visual>
        <collision>
            <origin rpy="0 0 0" xyz="0 0 0.07" />
            <geometry>
                <cylinder length="0.14" radius="0.03" />
            </geometry>
        </collision>
        
<inertial>
            <mass value="1" />
            <inertia ixx="1.0" ixy="0.0" ixz="0.0" iyy="0.5" iyz="0.0" izz="1.0" />
        </inertial>

    </link>
    <joint name="joint3" type="revolute">
        <parent link="link2" />
        <child link="link3" />
        <origin rpy="0 3.14159 0" xyz="0 0 0.14" />
        <axis xyz="-1 0 0" />
        <limit effort="300" lower="-2.62" upper="2.62" velocity="1" />
        <dynamics damping="50" friction="1" />
    </joint>
    <!-- LINK3 -->
    <link name="link3">
        <visual>
            <origin rpy="0 0 0" xyz="0 0 -0.11" />
            <geometry>
                <cylinder length="0.22" radius="0.03" />
            </geometry>
            <material name="Blue" />
        </visual>
        <collision>
            <origin rpy="0 0 0" xyz="0 0 -0.11" />
            <geometry>
                <cylinder length="0.22" radius="0.03" />
            </geometry>
        </collision>
        
<inertial>
            <mass value="1" />
            <inertia ixx="1.0" ixy="0.0" ixz="0.0" iyy="0.5" iyz="0.0" izz="1.0" />
        </inertial>

    </link>
    <joint name="joint4" type="revolute">
        <parent link="link3" />
        <child link="link4" />
        <origin rpy="0 1.570795 3.14159" xyz="0.0 0.0 -0.22" />
        <axis xyz="1 0 0" />
        <limit effort="300" lower="-2.62" upper="2.62" velocity="1" />
        <dynamics damping="50" friction="1" />
    </joint>
    <!-- LINK4 -->
    <link name="link4">
        <visual>
            <origin rpy="0 1.570795 0" xyz="0.03 0 0" />
            <geometry>
                <cylinder length="0.06" radius="0.025" />
            </geometry>
            <material name="Black" />
        </visual>
        <collision>
            <origin rpy="0 1.570795 0" xyz="0.03 0 0" />
            <geometry>
                <cylinder length="0.06" radius="0.025" />
            </geometry>
        </collision>
        
<inertial>
            <mass value="1" />
            <inertia ixx="1.0" ixy="0.0" ixz="0.0" iyy="0.5" iyz="0.0" izz="1.0" />
        </inertial>

    </link>
    <joint name="joint5" type="revolute">
        <parent link="link4" />
        <child link="link5" />
        <origin rpy="0 1.570795 0" xyz="0.06 0.0 0.0" />
        <axis xyz="1 0 0" />
        <limit effort="300" lower="-2.62" upper="2.62" velocity="1" />
        <dynamics damping="50" friction="1" />
    </joint>
    <!-- LINK5 -->
    <link name="link5">
        <visual>
            <origin rpy="0 0 0" xyz="0 0 0.03" />
            <geometry>
                <cylinder length="0.06" radius="0.03" />
            </geometry>
            <material name="White" />
        </visual>
        <collision>
            <origin rpy="0 0 0" xyz="0 0 0.03 " />
            <geometry>
                <cylinder length="0.06" radius="0.03" />
            </geometry>
        </collision>
        
<inertial>
            <mass value="1" />
            <inertia ixx="1.0" ixy="0.0" ixz="0.0" iyy="0.5" iyz="0.0" izz="1.0" />
        </inertial>

    </link>
    <joint name="joint6" type="revolute">
        <parent link="link5" />
        <child link="link6" />
        <origin rpy="4.712385 -1.570795 0" xyz="0 0 0.06" />
        <axis xyz="1 0 0" />
        <limit effort="300" lower="-6.28" upper="6.28" velocity="1" />
        <dynamics damping="50" friction="1" />
    </joint>
    <!-- LINK6 -->
    <link name="link6">
        <visual>
            <origin rpy="0 1.570795 0" xyz="0.01 0 0 " />
            <geometry>
                <cylinder length="0.02" radius="0.04" />
            </geometry>
            <material name="Blue" />
        </visual>
        <collision>
            <origin rpy="0 1.570795 0" xyz="0.01 0 0" />
            <geometry>
                <cylinder length="0.02" radius="0.04" />
            </geometry>
        </collision>
        
<inertial>
            <mass value="1" />
            <inertia ixx="1.0" ixy="0.0" ixz="0.0" iyy="0.5" iyz="0.0" izz="1.0" />
        </inertial>

    </link>
    <!-- gripper -->
    <joint name="finger_joint1" type="prismatic">
        <parent link="link6" />
        <child link="gripper_finger_link1" />
        <origin xyz="0.0 0 0" />
        <axis xyz="0 1 0" />
        <limit effort="100" lower="0" upper="0.06" velocity="1.0" />
        <dynamics damping="50" friction="1" />
    </joint>
    <!-- LEFT GRIPPER AFT LINK -->
    <link name="gripper_finger_link1">
        <visual>
            <origin xyz="0.04 -0.03 0" />
            <geometry>
                <box size="0.08 0.01 0.01" />
            </geometry>
            <material name="White" />
        </visual>
        
<inertial>
            <mass value="1" />
            <inertia ixx="1.0" ixy="0.0" ixz="0.0" iyy="0.5" iyz="0.0" izz="1.0" />
        </inertial>

    </link>
    <joint name="finger_joint2" type="fixed">
        <parent link="link6" />
        <child link="gripper_finger_link2" />
        <origin xyz="0.0 0 0" />
    </joint>
    <!-- RIGHT GRIPPER AFT LINK -->
    <link name="gripper_finger_link2">
        <visual>
            <origin xyz="0.04 0.03 0" />
            <geometry>
                <box size="0.08 0.01 0.01" />
            </geometry>
            <material name="White" />
        </visual>
        
<inertial>
            <mass value="1" />
            <inertia ixx="1.0" ixy="0.0" ixz="0.0" iyy="0.5" iyz="0.0" izz="1.0" />
        </inertial>

    </link>
    <!-- Grasping frame -->
    <link name="grasping_frame" />
    <joint name="grasping_frame_joint" type="fixed">
        <parent link="link6" />
        <child link="grasping_frame" />
        <origin rpy="0 0 0" xyz="0.08 0 0" />
    </joint>
    <!-- Gazebo -->
    <gazebo reference="bottom_link">
        <material>Gazebo/White</material>
    </gazebo>
    <gazebo reference="base_link">
        <material>Gazebo/White</material>
    </gazebo>
    <gazebo reference="link1">
        <material>Gazebo/Blue</material>
    </gazebo>
    <gazebo reference="link2">
        <material>Gazebo/White</material>
    </gazebo>
    <gazebo reference="link3">
        <material>Gazebo/Blue</material>
    </gazebo>
    <gazebo reference="link4">
        <material>Gazebo/Black</material>
    </gazebo>
    <gazebo reference="link5">
        <material>Gazebo/White</material>
    </gazebo>
    <gazebo reference="link6">
        <material>Gazebo/Blue</material>
    </gazebo>
    <gazebo reference="gripper_finger_link1">
        <material>Gazebo/White</material>
    </gazebo>
    <gazebo reference="gripper_finger_link2">
        <material>Gazebo/White</material>
    </gazebo>
    
<transmission name="tran1">
        <type>transmission_interface/SimpleTransmission</type>
        <joint name="joint1">
            <hardwareInterface>hardware_interface/PositionJointInterface</hardwareInterface>
        </joint>
        <actuator name="motor1">
            <hardwareInterface>hardware_interface/PositionJointInterface</hardwareInterface>
            <mechanicalReduction>1</mechanicalReduction>
        </actuator>
    </transmission>
    <transmission name="tran1">
        <type>transmission_interface/SimpleTransmission</type>
        <joint name="joint2">
            <hardwareInterface>hardware_interface/PositionJointInterface</hardwareInterface>
        </joint>
        <actuator name="motor1">
            <hardwareInterface>hardware_interface/PositionJointInterface</hardwareInterface>
            <mechanicalReduction>1</mechanicalReduction>
        </actuator>
    </transmission>
    <transmission name="tran1">
        <type>transmission_interface/SimpleTransmission</type>
        <joint name="joint3">
            <hardwareInterface>hardware_interface/PositionJointInterface</hardwareInterface>
        </joint>
        <actuator name="motor1">
            <hardwareInterface>hardware_interface/PositionJointInterface</hardwareInterface>
            <mechanicalReduction>1</mechanicalReduction>
        </actuator>
    </transmission>
    <transmission name="tran1">
        <type>transmission_interface/SimpleTransmission</type>
        <joint name="joint4">
            <hardwareInterface>hardware_interface/PositionJointInterface</hardwareInterface>
        </joint>
        <actuator name="motor1">
            <hardwareInterface>hardware_interface/PositionJointInterface</hardwareInterface>
            <mechanicalReduction>1</mechanicalReduction>
        </actuator>
    </transmission>
    <transmission name="tran1">
        <type>transmission_interface/SimpleTransmission</type>
        <joint name="joint5">
            <hardwareInterface>hardware_interface/PositionJointInterface</hardwareInterface>
        </joint>
        <actuator name="motor1">
            <hardwareInterface>hardware_interface/PositionJointInterface</hardwareInterface>
            <mechanicalReduction>1</mechanicalReduction>
        </actuator>
    </transmission>
    <transmission name="tran1">
        <type>transmission_interface/SimpleTransmission</type>
        <joint name="joint6">
            <hardwareInterface>hardware_interface/PositionJointInterface</hardwareInterface>
        </joint>
        <actuator name="motor1">
            <hardwareInterface>hardware_interface/PositionJointInterface</hardwareInterface>
            <mechanicalReduction>1</mechanicalReduction>
        </actuator>
    </transmission>
    <transmission name="tran1">
        <type>transmission_interface/SimpleTransmission</type>
        <joint name="finger_joint1">
            <hardwareInterface>hardware_interface/PositionJointInterface</hardwareInterface>
        </joint>
        <actuator name="motor1">
            <hardwareInterface>hardware_interface/PositionJointInterface</hardwareInterface>
            <mechanicalReduction>1</mechanicalReduction>
        </actuator>
    </transmission>
    <!-- ros_control plugin -->
    <gazebo>
        <plugin filename="libgazebo_ros_control.so" name="gazebo_ros_control">
            <robotNamespace>/hharm</robotNamespace>
        </plugin>
    </gazebo>
    <transmission name="trans_joint1">
        <type>transmission_interface/SimpleTransmission</type>
        <joint name="joint1">
            <hardwareInterface>hardware_interface/EffortJointInterface</hardwareInterface>
        </joint>
        <actuator name="joint1_motor">
            <hardwareInterface>hardware_interface/EffortJointInterface</hardwareInterface>
            <mechanicalReduction>1</mechanicalReduction>
        </actuator>
    </transmission>
    <transmission name="trans_joint2">
        <type>transmission_interface/SimpleTransmission</type>
        <joint name="joint2">
            <hardwareInterface>hardware_interface/EffortJointInterface</hardwareInterface>
        </joint>
        <actuator name="joint2_motor">
            <hardwareInterface>hardware_interface/EffortJointInterface</hardwareInterface>
            <mechanicalReduction>1</mechanicalReduction>
        </actuator>
    </transmission>
    <transmission name="trans_joint3">
        <type>transmission_interface/SimpleTransmission</type>
        <joint name="joint3">
            <hardwareInterface>hardware_interface/EffortJointInterface</hardwareInterface>
        </joint>
        <actuator name="joint3_motor">
            <hardwareInterface>hardware_interface/EffortJointInterface</hardwareInterface>
            <mechanicalReduction>1</mechanicalReduction>
        </actuator>
    </transmission>
    <transmission name="trans_joint4">
        <type>transmission_interface/SimpleTransmission</type>
        <joint name="joint4">
            <hardwareInterface>hardware_interface/EffortJointInterface</hardwareInterface>
        </joint>
        <actuator name="joint4_motor">
            <hardwareInterface>hardware_interface/EffortJointInterface</hardwareInterface>
            <mechanicalReduction>1</mechanicalReduction>
        </actuator>
    </transmission>
    <transmission name="trans_joint5">
        <type>transmission_interface/SimpleTransmission</type>
        <joint name="joint5">
            <hardwareInterface>hardware_interface/EffortJointInterface</hardwareInterface>
        </joint>
        <actuator name="joint5_motor">
            <hardwareInterface>hardware_interface/EffortJointInterface</hardwareInterface>
            <mechanicalReduction>1</mechanicalReduction>
        </actuator>
    </transmission>
    <transmission name="trans_joint6">
        <type>transmission_interface/SimpleTransmission</type>
        <joint name="joint6">
            <hardwareInterface>hardware_interface/EffortJointInterface</hardwareInterface>
        </joint>
        <actuator name="joint6_motor">
            <hardwareInterface>hardware_interface/EffortJointInterface</hardwareInterface>
            <mechanicalReduction>1</mechanicalReduction>
        </actuator>
    </transmission>
    <transmission name="trans_finger_joint1">
        <type>transmission_interface/SimpleTransmission</type>
        <joint name="finger_joint1">
            <hardwareInterface>hardware_interface/EffortJointInterface</hardwareInterface>
        </joint>
        <actuator name="finger_joint1_motor">
            <hardwareInterface>hardware_interface/EffortJointInterface</hardwareInterface>
            <mechanicalReduction>1</mechanicalReduction>
        </actuator>
    </transmission>
    <gazebo>
        <plugin name="gazebo_ros_control" filename="libgazebo_ros_control.so">
            <robotNamespace>/</robotNamespace>
        </plugin>
    </gazebo>
</robot>
